Workbook

Sheet 음식DB
B1: 카테고리 | C1: 음식 | D1: 음식구분 | E1: 제철 | F1: 재료 | G1: 영양분류 | H1: 주재료분류 | I1: 조리방식 | J1: 조리시간 | K1: 알레르기 | L1: 아침가능 | M1: 점심가능 | N1: 저녁가능 | O1: 비고 | P1: 식사구분 자동 | Q1: data.js 복사용
B2: 간단식 | C2: 오트밀 바나나볼 | D2: 간단식 | E2: 사계절 | F2: 오트밀, 우유, 바나나, 견과류 | G2: 탄수화물+식이섬유 | H2: 곡류 | I2: 간단식 | J2: 10분 | K2: 우유, 견과류 | L2: Y | P2: =IF($C2="","",_xlfn.TEXTJOIN(", ",TRUE,IF(UPPER(TRIM($L2))="Y","아침",""),IF(UPPER(TRIM($M2))="Y","점심",""),IF(UPPER(TRIM($N2))="Y","저녁",""))) -> 아침 | Q2: =IF($C2="","","{ 카테고리: """&$B2&""", 음식: """&$C2&""", 음식구분: """&$D2&""", 제철: """&$E2&""", 재료: """&$F2&""", 식사구분: ["&_xlfn.TEXTJOIN(", ",TRUE,IF(UPPER(TRIM($L2))="Y",CHAR(34)&"아침"&CHAR(34),""),IF(UPPER(TRIM($M2))="Y",CHAR(34)&"점심"&CHAR(34),""),IF(UPPER(TRIM($N2))="Y",CHAR(34)&"저녁"&CHAR(34),""))&"], 영양분류: """&$G2&""", 주재료분류: """&$H2&""", 조리방식: """&$I2&""", 조리시간: """&$J2&""", 알레르기: """&$K2&""" },") -> { 카테고리: "간단식", 음식: "오트밀 바나나볼", 음식구분: "간단식", 제철: "사계절", 재료: "오트밀, 우유, 바나나, 견과류", 식사구분: ["아침"], 영양분류: "탄수화물+식이섬유", 주재료분류: "곡류", 조리방식: "간단식", 조리시간: "10분", 알레르기: "우유, 견과류" },
B3: 간단식 | C3: 그릭요거트 과일볼 | D3: 간단식 | E3: 사계절 | F3: 그릭요거트, 딸기, 블루베리, 그래놀라 | G3: 단백질+비타민 | H3: 유제품 | I3: 간단식 | J3: 5분 | K3: 우유 | L3: Y | P3: =IF($C3="","",_xlfn.TEXTJOIN(", ",TRUE,IF(UPPER(TRIM($L3))="Y","아침",""),IF(UPPER(TRIM($M3))="Y","점심",""),IF(UPPER(TRIM($N3))="Y","저녁",""))) -> 아침 | Q3: =IF($C3="","","{ 카테고리: """&$B3&""", 음식: """&$C3&""", 음식구분: """&$D3&""", 제철: """&$E3&""", 재료: """&$F3&""", 식사구분: ["&_xlfn.TEXTJOIN(", ",TRUE,IF(UPPER(TRIM($L3))="Y",CHAR(34)&"아침"&CHAR(34),""),IF(UPPER(TRIM($M3))="Y",CHAR(34)&"점심"&CHAR(34),""),IF(UPPER(TRIM($N3))="Y",CHAR(34)&"저녁"&CHAR(34),""))&"], 영양분류: """&$G3&""", 주재료분류: """&$H3&""", 조리방식: """&$I3&""", 조리시간: """&$J3&""", 알레르기: """&$K3&""" },") -> { 카테고리: "간단식", 음식: "그릭요거트 과일볼", 음식구분: "간단식", 제철: "사계절", 재료: "그릭요거트, 딸기, 블루베리, 그래놀라", 식사구분: ["아침"], 영양분류: "단백질+비타민", 주재료분류: "유제품", 조리방식: "간단식", 조리시간: "5분", 알레르기: "우유" },
B4: 간단식 | C4: 삶은계란 토스트 | D4: 간단식 | E4: 사계절 | F4: 식빵, 계란, 양상추, 토마토 | G4: 단백질+탄수화물 | H4: 계란 | I4: 간단식 | J4: 15분 | K4: 계란, 밀 | L4: Y | P4: =IF($C4="","",_xlfn.TEXTJOIN(", ",TRUE,IF(UPPER(TRIM($L4))="Y","아침",""),IF(UPPER(TRIM($M4))="Y","점심",""),IF(UPPER(TRIM($N4))="Y","저녁",""))) -> 아침 | Q4: =IF($C4="","","{ 카테고리: """&$B4&""", 음식: """&$C4&""", 음식구분: """&$D4&""", 제철: """&$E4&""", 재료: """&$F4&""", 식사구분: ["&_xlfn.TEXTJOIN(", ",TRUE,IF(UPPER(TRIM($L4))="Y",CHAR(34)&"아침"&CHAR(34),""),IF(UPPER(TRIM($M4))="Y",CHAR(34)&"점심"&CHAR(34),""),IF(UPPER(TRIM($N4))="Y",CHAR(34)&"저녁"&CHAR(34),""))&"], 영양분류: """&$G4&""", 주재료분류: """&$H4&""", 조리방식: """&$I4&""", 조리시간: """&$J4&""", 알레르기: """&$K4&""" },") -> { 카테고리: "간단식", 음식: "삶은계란 토스트", 음식구분: "간단식", 제철: "사계절", 재료: "식빵, 계란, 양상추, 토마토", 식사구분: ["아침"], 영양분류: "단백질+탄수화물", 주재료분류: "계란", 조리방식: "간단식", 조리시간: "15분", 알레르기: "계란, 밀" },
B5: 간단식 | C5: 닭가슴살 샌드위치 | D5: 간단식 | E5: 사계절 | F5: 식빵, 닭가슴살, 양상추, 토마토, 치즈 | G5: 고단백 | H5: 육류 | I5: 간단식 | J5: 15분 | K5: 밀, 우유 | L5: Y | M5: Y | P5: =IF($C5="","",_xlfn.TEXTJOIN(", ",TRUE,IF(UPPER(TRIM($L5))="Y","아침",""),IF(UPPER(TRIM($M5))="Y","점심",""),IF(UPPER(TRIM($N5))="Y","저녁",""))) -> 아침, 점심 | Q5: =IF($C5="","","{ 카테고리: """&$B5&""", 음식: """&$C5&""", 음식구분: """&$D5&""", 제철: """&$E5&""", 재료: """&$F5&""", 식사구분: ["&_xlfn.TEXTJOIN(", ",TRUE,IF(UPPER(TRIM($L5))="Y",CHAR(34)&"아침"&CHAR(34),""),IF(UPPER(TRIM($M5))="Y",CHAR(34)&"점심"&CHAR(34),""),IF(UPPER(TRIM($N5))="Y",CHAR(34)&"저녁"&CHAR(34),""))&"], 영양분류: """&$G5&""", 주재료분류: """&$H5&""", 조리방식: """&$I5&""", 조리시간: """&$J5&""", 알레르기: """&$K5&""" },") -> { 카테고리: "간단식", 음식: "닭가슴살 샌드위치", 음식구분: "간단식", 제철: "사계절", 재료: "식빵, 닭가슴살, 양상추, 토마토, 치즈", 식사구분: ["아침", "점심"], 영양분류: "고단백", 주재료분류: "육류", 조리방식: "간단식", 조리시간: "15분", 알레르기: "밀, 우유" },
B6: 간단식 | C6: 계란국과 밥 | D6: 간단식 | E6: 사계절 | F6: 계란, 대파, 밥, 육수 | G6: 가벼운 한식 | H6: 계란 | I6: 국물 | J6: 15분 | K6: 계란 | L6: Y | N6: Y | P6: =IF($C6="","",_xlfn.TEXTJOIN(", ",TRUE,IF(UPPER(TRIM($L6))="Y","아침",""),IF(UPPER(TRIM($M6))="Y","점심",""),IF(UPPER(TRIM($N6))="Y","저녁",""))) -> 아침, 저녁 | Q6: =IF($C6="","","{ 카테고리: """&$B6&""", 음식: """&$C6&""", 음식구분: """&$D6&""", 제철: """&$E6&""", 재료: """&$F6&""", 식사구분: ["&_xlfn.TEXTJOIN(", ",TRUE,IF(UPPER(TRIM($L6))="Y",CHAR(34)&"아침"&CHAR(34),""),IF(UPPER(TRIM($M6))="Y",CHAR(34)&"점심"&CHAR(34),""),IF(UPPER(TRIM($N6))="Y",CHAR(34)&"저녁"&CHAR(34),""))&"], 영양분류: """&$G6&""", 주재료분류: """&$H6&""", 조리방식: """&$I6&""", 조리시간: """&$J6&""", 알레르기: """&$K6&""" },") -> { 카테고리: "간단식", 음식: "계란국과 밥", 음식구분: "간단식", 제철: "사계절", 재료: "계란, 대파, 밥, 육수", 식사구분: ["아침", "저녁"], 영양분류: "가벼운 한식", 주재료분류: "계란", 조리방식: "국물", 조리시간: "15분", 알레르기: "계란" },
B7: 간단식 | C7: 누룽지와 김 | D7: 간단식 | E7: 사계절 | F7: 누룽지, 김, 간장 | G7: 가벼운 탄수화물 | H7: 곡류 | I7: 국물 | J7: 10분 | K7: 대두 | L7: Y | P7: =IF($C7="","",_xlfn.TEXTJOIN(", ",TRUE,IF(UPPER(TRIM($L7))="Y","아침",""),IF(UPPER(TRIM($M7))="Y","점심",""),IF(UPPER(TRIM($N7))="Y","저녁",""))) -> 아침 | Q7: =IF($C7="","","{ 카테고리: """&$B7&""", 음식: """&$C7&""", 음식구분: """&$D7&""", 제철: """&$E7&""", 재료: """&$F7&""", 식사구분: ["&_xlfn.TEXTJOIN(", ",TRUE,IF(UPPER(TRIM($L7))="Y",CHAR(34)&"아침"&CHAR(34),""),IF(UPPER(TRIM($M7))="Y",CHAR(34)&"점심"&CHAR(34),""),IF(UPPER(TRIM($N7))="Y",CHAR(34)&"저녁"&CHAR(34),""))&"], 영양분류: """&$G7&""", 주재료분류: """&$H7&""", 조리방식: """&$I7&""", 조리시간: """&$J7&""", 알레르기: """&$K7&""" },") -> { 카테고리: "간단식", 음식: "누룽지와 김", 음식구분: "간단식", 제철: "사계절", 재료: "누룽지, 김, 간장", 식사구분: ["아침"], 영양분류: "가벼운 탄수화물", 주재료분류: "곡류", 조리방식: "국물", 조리시간: "10분", 알레르기: "대두" },
B8: 간단식 | C8: 두부 샐러드 | D8: 간단식 | E8: 사계절 | F8: 두부, 양상추, 토마토, 오리엔탈드레싱 | G8: 식물성 단백질 | H8: 두부 | I8: 생식 | J8: 10분 | K8: 대두 | L8: Y | M8: Y | P8: =IF($C8="","",_xlfn.TEXTJOIN(", ",TRUE,IF(UPPER(TRIM($L8))="Y","아침",""),IF(UPPER(TRIM($M8))="Y","점심",""),IF(UPPER(TRIM($N8))="Y","저녁",""))) -> 아침, 점심 | Q8: =IF($C8="","","{ 카테고리: """&$B8&""", 음식: """&$C8&""", 음식구분: """&$D8&""", 제철: """&$E8&""", 재료: """&$F8&""", 식사구분: ["&_xlfn.TEXTJOIN(", ",TRUE,IF(UPPER(TRIM($L8))="Y",CHAR(34)&"아침"&CHAR(34),""),IF(UPPER(TRIM($M8))="Y",CHAR(34)&"점심"&CHAR(34),""),IF(UPPER(TRIM($N8))="Y",CHAR(34)&"저녁"&CHAR(34),""))&"], 영양분류: """&$G8&""", 주재료분류: """&$H8&""", 조리방식: """&$I8&""", 조리시간: """&$J8&""", 알레르기: """&$K8&""" },") -> { 카테고리: "간단식", 음식: "두부 샐러드", 음식구분: "간단식", 제철: "사계절", 재료: "두부, 양상추, 토마토, 오리엔탈드레싱", 식사구분: ["아침", "점심"], 영양분류: "식물성 단백질", 주재료분류: "두부", 조리방식: "생식", 조리시간: "10분", 알레르기: "대두" },
B9: 간단식 | C9: 참치마요 주먹밥 | D9: 간단식 | E9: 사계절 | F9: 밥, 참치, 김, 마요네즈 | G9: 단백질+탄수화물 | H9: 생선 | I9: 간단식 | J9: 10분 | K9: 계란, 생선 | L9: Y | M9: Y | P9: =IF($C9="","",_xlfn.TEXTJOIN(", ",TRUE,IF(UPPER(TRIM($L9))="Y","아침",""),IF(UPPER(TRIM($M9))="Y","점심",""),IF(UPPER(TRIM($N9))="Y","저녁",""))) -> 아침, 점심 | Q9: =IF($C9="","","{ 카테고리: """&$B9&""", 음식: """&$C9&""", 음식구분: """&$D9&""", 제철: """&$E9&""", 재료: """&$F9&""", 식사구분: ["&_xlfn.TEXTJOIN(", ",TRUE,IF(UPPER(TRIM($L9))="Y",CHAR(34)&"아침"&CHAR(34),""),IF(UPPER(TRIM($M9))="Y",CHAR(34)&"점심"&CHAR(34),""),IF(UPPER(TRIM($N9))="Y",CHAR(34)&"저녁"&CHAR(34),""))&"], 영양분류: """&$G9&""", 주재료분류: """&$H9&""", 조리방식: """&$I9&""", 조리시간: """&$J9&""", 알레르기: """&$K9&""" },") -> { 카테고리: "간단식", 음식: "참치마요 주먹밥", 음식구분: "간단식", 제철: "사계절", 재료: "밥, 참치, 김, 마요네즈", 식사구분: ["아침", "점심"], 영양분류: "단백질+탄수화물", 주재료분류: "생선", 조리방식: "간단식", 조리시간: "10분", 알레르기: "계란, 생선" },
B10: 한식 | C10: 김치찌개 | D10: 찌개 | E10: 사계절 | F10: 김치, 돼지고기, 두부 | G10: 단백질+국물 | H10: 육류 | I10: 찌개 | J10: 30분 | K10: 대두 | M10: Y | N10: Y | P10: =IF($C10="","",_xlfn.TEXTJOIN(", ",TRUE,IF(UPPER(TRIM($L10))="Y","아침",""),IF(UPPER(TRIM($M10))="Y","점심",""),IF(UPPER(TRIM($N10))="Y","저녁",""))) -> 점심, 저녁 | Q10: =IF($C10="","","{ 카테고리: """&$B10&""", 음식: """&$C10&""", 음식구분: """&$D10&""", 제철: """&$E10&""", 재료: """&$F10&""", 식사구분: ["&_xlfn.TEXTJOIN(", ",TRUE,IF(UPPER(TRIM($L10))="Y",CHAR(34)&"아침"&CHAR(34),""),IF(UPPER(TRIM($M10))="Y",CHAR(34)&"점심"&CHAR(34),""),IF(UPPER(TRIM($N10))="Y",CHAR(34)&"저녁"&CHAR(34),""))&"], 영양분류: """&$G10&""", 주재료분류: """&$H10&""", 조리방식: """&$I10&""", 조리시간: """&$J10&""", 알레르기: """&$K10&""" },") -> { 카테고리: "한식", 음식: "김치찌개", 음식구분: "찌개", 제철: "사계절", 재료: "김치, 돼지고기, 두부", 식사구분: ["점심", "저녁"], 영양분류: "단백질+국물", 주재료분류: "육류", 조리방식: "찌개", 조리시간: "30분", 알레르기: "대두" },
B11: 한식 | C11: 비빔밥 | D11: 메인반찬 | E11: 사계절 | F11: 밥, 각종 나물, 계란, 다진 소고기 | G11: 균형식 | H11: 밥 | I11: 비빔 | J11: 30분 | K11: 계란 | M11: Y | N11: Y | P11: =IF($C11="","",_xlfn.TEXTJOIN(", ",TRUE,IF(UPPER(TRIM($L11))="Y","아침",""),IF(UPPER(TRIM($M11))="Y","점심",""),IF(UPPER(TRIM($N11))="Y","저녁",""))) -> 점심, 저녁 | Q11: =IF($C11="","","{ 카테고리: """&$B11&""", 음식: """&$C11&""", 음식구분: """&$D11&""", 제철: """&$E11&""", 재료: """&$F11&""", 식사구분: ["&_xlfn.TEXTJOIN(", ",TRUE,IF(UPPER(TRIM($L11))="Y",CHAR(34)&"아침"&CHAR(34),""),IF(UPPER(TRIM($M11))="Y",CHAR(34)&"점심"&CHAR(34),""),IF(UPPER(TRIM($N11))="Y",CHAR(34)&"저녁"&CHAR(34),""))&"], 영양분류: """&$G11&""", 주재료분류: """&$H11&""", 조리방식: """&$I11&""", 조리시간: """&$J11&""", 알레르기: """&$K11&""" },") -> { 카테고리: "한식", 음식: "비빔밥", 음식구분: "메인반찬", 제철: "사계절", 재료: "밥, 각종 나물, 계란, 다진 소고기", 식사구분: ["점심", "저녁"], 영양분류: "균형식", 주재료분류: "밥", 조리방식: "비빔", 조리시간: "30분", 알레르기: "계란" },
B12: 한식 | C12: 된장찌개 | D12: 찌개 | E12: 사계절 | F12: 두부, 애호박, 양파, 팽이버섯 | G12: 식물성 단백질+국물 | H12: 두부 | I12: 찌개 | J12: 25분 | K12: 대두 | L12: Y | M12: Y | N12: Y | P12: =IF($C12="","",_xlfn.TEXTJOIN(", ",TRUE,IF(UPPER(TRIM($L12))="Y","아침",""),IF(UPPER(TRIM($M12))="Y","점심",""),IF(UPPER(TRIM($N12))="Y","저녁",""))) -> 아침, 점심, 저녁 | Q12: =IF($C12="","","{ 카테고리: """&$B12&""", 음식: """&$C12&""", 음식구분: """&$D12&""", 제철: """&$E12&""", 재료: """&$F12&""", 식사구분: ["&_xlfn.TEXTJOIN(", ",TRUE,IF(UPPER(TRIM($L12))="Y",CHAR(34)&"아침"&CHAR(34),""),IF(UPPER(TRIM($M12))="Y",CHAR(34)&"점심"&CHAR(34),""),IF(UPPER(TRIM($N12))="Y",CHAR(34)&"저녁"&CHAR(34),""))&"], 영양분류: """&$G12&""", 주재료분류: """&$H12&""", 조리방식: """&$I12&""", 조리시간: """&$J12&""", 알레르기: """&$K12&""" },") -> { 카테고리: "한식", 음식: "된장찌개", 음식구분: "찌개", 제철: "사계절", 재료: "두부, 애호박, 양파, 팽이버섯", 식사구분: ["아침", "점심", "저녁"], 영양분류: "식물성 단백질+국물", 주재료분류: "두부", 조리방식: "찌개", 조리시간: "25분", 알레르기: "대두" },
B13: 한식 | C13: 제육볶음 | D13: 메인반찬 | E13: 사계절 | F13: 돼지고기, 양파, 대파, 양배추 | G13: 고단백 | H13: 육류 | I13: 볶음 | J13: 25분 | K13: 없음 | M13: Y | N13: Y | P13: =IF($C13="","",_xlfn.TEXTJOIN(", ",TRUE,IF(UPPER(TRIM($L13))="Y","아침",""),IF(UPPER(TRIM($M13))="Y","점심",""),IF(UPPER(TRIM($N13))="Y","저녁",""))) -> 점심, 저녁 | Q13: =IF($C13="","","{ 카테고리: """&$B13&""", 음식: """&$C13&""", 음식구분: """&$D13&""", 제철: """&$E13&""", 재료: """&$F13&""", 식사구분: ["&_xlfn.TEXTJOIN(", ",TRUE,IF(UPPER(TRIM($L13))="Y",CHAR(34)&"아침"&CHAR(34),""),IF(UPPER(TRIM($M13))="Y",CHAR(34)&"점심"&CHAR(34),""),IF(UPPER(TRIM($N13))="Y",CHAR(34)&"저녁"&CHAR(34),""))&"], 영양분류: """&$G13&""", 주재료분류: """&$H13&""", 조리방식: """&$I13&""", 조리시간: """&$J13&""", 알레르기: """&$K13&""" },") -> { 카테고리: "한식", 음식: "제육볶음", 음식구분: "메인반찬", 제철: "사계절", 재료: "돼지고기, 양파, 대파, 양배추", 식사구분: ["점심", "저녁"], 영양분류: "고단백", 주재료분류: "육류", 조리방식: "볶음", 조리시간: "25분", 알레르기: "없음" },
B14: 한식 | C14: 삼겹살 | D14: 메인반찬 | E14: 사계절 | F14: 돼지고기 삼겹살, 마늘, 상추, 깻잎 | G14: 고단백+고지방 | H14: 육류 | I14: 구이 | J14: 30분 | K14: 없음 | N14: Y | P14: =IF($C14="","",_xlfn.TEXTJOIN(", ",TRUE,IF(UPPER(TRIM($L14))="Y","아침",""),IF(UPPER(TRIM($M14))="Y","점심",""),IF(UPPER(TRIM($N14))="Y","저녁",""))) -> 저녁 | Q14: =IF($C14="","","{ 카테고리: """&$B14&""", 음식: """&$C14&""", 음식구분: """&$D14&""", 제철: """&$E14&""", 재료: """&$F14&""", 식사구분: ["&_xlfn.TEXTJOIN(", ",TRUE,IF(UPPER(TRIM($L14))="Y",CHAR(34)&"아침"&CHAR(34),""),IF(UPPER(TRIM($M14))="Y",CHAR(34)&"점심"&CHAR(34),""),IF(UPPER(TRIM($N14))="Y",CHAR(34)&"저녁"&CHAR(34),""))&"], 영양분류: """&$G14&""", 주재료분류: """&$H14&""", 조리방식: """&$I14&""", 조리시간: """&$J14&""", 알레르기: """&$K14&""" },") -> { 카테고리: "한식", 음식: "삼겹살", 음식구분: "메인반찬", 제철: "사계절", 재료: "돼지고기 삼겹살, 마늘, 상추, 깻잎", 식사구분: ["저녁"], 영양분류: "고단백+고지방", 주재료분류: "육류", 조리방식: "구이", 조리시간: "30분", 알레르기: "없음" },
B15: 한식 | C15: 보쌈 | D15: 메인반찬 | E15: 사계절 | F15: 돼지고기 수육, 배추, 무 | G15: 고단백 | H15: 육류 | I15: 찜 | J15: 1시간 | K15: 없음 | N15: Y | P15: =IF($C15="","",_xlfn.TEXTJOIN(", ",TRUE,IF(UPPER(TRIM($L15))="Y","아침",""),IF(UPPER(TRIM($M15))="Y","점심",""),IF(UPPER(TRIM($N15))="Y","저녁",""))) -> 저녁 | Q15: =IF($C15="","","{ 카테고리: """&$B15&""", 음식: """&$C15&""", 음식구분: """&$D15&""", 제철: """&$E15&""", 재료: """&$F15&""", 식사구분: ["&_xlfn.TEXTJOIN(", ",TRUE,IF(UPPER(TRIM($L15))="Y",CHAR(34)&"아침"&CHAR(34),""),IF(UPPER(TRIM($M15))="Y",CHAR(34)&"점심"&CHAR(34),""),IF(UPPER(TRIM($N15))="Y",CHAR(34)&"저녁"&CHAR(34),""))&"], 영양분류: """&$G15&""", 주재료분류: """&$H15&""", 조리방식: """&$I15&""", 조리시간: """&$J15&""", 알레르기: """&$K15&""" },") -> { 카테고리: "한식", 음식: "보쌈", 음식구분: "메인반찬", 제철: "사계절", 재료: "돼지고기 수육, 배추, 무", 식사구분: ["저녁"], 영양분류: "고단백", 주재료분류: "육류", 조리방식: "찜", 조리시간: "1시간", 알레르기: "없음" },
B16: 한식 | C16: 감자탕 | D16: 국/탕 | E16: 겨울 | F16: 돼지등뼈, 감자, 우거지, 깻잎 | G16: 고단백+국물 | H16: 육류 | I16: 탕 | J16: 1시간 | K16: 없음 | M16: Y | N16: Y | P16: =IF($C16="","",_xlfn.TEXTJOIN(", ",TRUE,IF(UPPER(TRIM($L16))="Y","아침",""),IF(UPPER(TRIM($M16))="Y","점심",""),IF(UPPER(TRIM($N16))="Y","저녁",""))) -> 점심, 저녁 | Q16: =IF($C16="","","{ 카테고리: """&$B16&""", 음식: """&$C16&""", 음식구분: """&$D16&""", 제철: """&$E16&""", 재료: """&$F16&""", 식사구분: ["&_xlfn.TEXTJOIN(", ",TRUE,IF(UPPER(TRIM($L16))="Y",CHAR(34)&"아침"&CHAR(34),""),IF(UPPER(TRIM($M16))="Y",CHAR(34)&"점심"&CHAR(34),""),IF(UPPER(TRIM($N16))="Y",CHAR(34)&"저녁"&CHAR(34),""))&"], 영양분류: """&$G16&""", 주재료분류: """&$H16&""", 조리방식: """&$I16&""", 조리시간: """&$J16&""", 알레르기: """&$K16&""" },") -> { 카테고리: "한식", 음식: "감자탕", 음식구분: "국/탕", 제철: "겨울", 재료: "돼지등뼈, 감자, 우거지, 깻잎", 식사구분: ["점심", "저녁"], 영양분류: "고단백+국물", 주재료분류: "육류", 조리방식: "탕", 조리시간: "1시간", 알레르기: "없음" },
B17: 한식 | C17: 부대찌개 | D17: 찌개 | E17: 사계절 | F17: 햄, 소시지, 김치, 라면사리, 대파 | G17: 고열량 | H17: 가공육 | I17: 찌개 | J17: 25분 | K17: 밀 | M17: Y | N17: Y | P17: =IF($C17="","",_xlfn.TEXTJOIN(", ",TRUE,IF(UPPER(TRIM($L17))="Y","아침",""),IF(UPPER(TRIM($M17))="Y","점심",""),IF(UPPER(TRIM($N17))="Y","저녁",""))) -> 점심, 저녁 | Q17: =IF($C17="","","{ 카테고리: """&$B17&""", 음식: """&$C17&""", 음식구분: """&$D17&""", 제철: """&$E17&""", 재료: """&$F17&""", 식사구분: ["&_xlfn.TEXTJOIN(", ",TRUE,IF(UPPER(TRIM($L17))="Y",CHAR(34)&"아침"&CHAR(34),""),IF(UPPER(TRIM($M17))="Y",CHAR(34)&"점심"&CHAR(34),""),IF(UPPER(TRIM($N17))="Y",CHAR(34)&"저녁"&CHAR(34),""))&"], 영양분류: """&$G17&""", 주재료분류: """&$H17&""", 조리방식: """&$I17&""", 조리시간: """&$J17&""", 알레르기: """&$K17&""" },") -> { 카테고리: "한식", 음식: "부대찌개", 음식구분: "찌개", 제철: "사계절", 재료: "햄, 소시지, 김치, 라면사리, 대파", 식사구분: ["점심", "저녁"], 영양분류: "고열량", 주재료분류: "가공육", 조리방식: "찌개", 조리시간: "25분", 알레르기: "밀" },
B18: 한식 | C18: 삼계탕 | D18: 국/탕 | E18: 여름 | F18: 닭고기, 인삼, 찹쌀, 대추, 마늘 | G18: 고단백+보양식 | H18: 육류 | I18: 탕 | J18: 1시간 | K18: 없음 | M18: Y | N18: Y | P18: =IF($C18="","",_xlfn.TEXTJOIN(", ",TRUE,IF(UPPER(TRIM($L18))="Y","아침",""),IF(UPPER(TRIM($M18))="Y","점심",""),IF(UPPER(TRIM($N18))="Y","저녁",""))) -> 점심, 저녁 | Q18: =IF($C18="","","{ 카테고리: """&$B18&""", 음식: """&$C18&""", 음식구분: """&$D18&""", 제철: """&$E18&""", 재료: """&$F18&""", 식사구분: ["&_xlfn.TEXTJOIN(", ",TRUE,IF(UPPER(TRIM($L18))="Y",CHAR(34)&"아침"&CHAR(34),""),IF(UPPER(TRIM($M18))="Y",CHAR(34)&"점심"&CHAR(34),""),IF(UPPER(TRIM($N18))="Y",CHAR(34)&"저녁"&CHAR(34),""))&"], 영양분류: """&$G18&""", 주재료분류: """&$H18&""", 조리방식: """&$I18&""", 조리시간: """&$J18&""", 알레르기: """&$K18&""" },") -> { 카테고리: "한식", 음식: "삼계탕", 음식구분: "국/탕", 제철: "여름", 재료: "닭고기, 인삼, 찹쌀, 대추, 마늘", 식사구분: ["점심", "저녁"], 영양분류: "고단백+보양식", 주재료분류: "육류", 조리방식: "탕", 조리시간: "1시간", 알레르기: "없음" },
B19: 한식 | C19: 갈비탕 | D19: 국/탕 | E19: 사계절 | F19: 소갈비, 당면, 대파, 무 | G19: 고단백+국물 | H19: 육류 | I19: 탕 | J19: 1시간 | K19: 없음 | M19: Y | N19: Y | P19: =IF($C19="","",_xlfn.TEXTJOIN(", ",TRUE,IF(UPPER(TRIM($L19))="Y","아침",""),IF(UPPER(TRIM($M19))="Y","점심",""),IF(UPPER(TRIM($N19))="Y","저녁",""))) -> 점심, 저녁 | Q19: =IF($C19="","","{ 카테고리: """&$B19&""", 음식: """&$C19&""", 음식구분: """&$D19&""", 제철: """&$E19&""", 재료: """&$F19&""", 식사구분: ["&_xlfn.TEXTJOIN(", ",TRUE,IF(UPPER(TRIM($L19))="Y",CHAR(34)&"아침"&CHAR(34),""),IF(UPPER(TRIM($M19))="Y",CHAR(34)&"점심"&CHAR(34),""),IF(UPPER(TRIM($N19))="Y",CHAR(34)&"저녁"&CHAR(34),""))&"], 영양분류: """&$G19&""", 주재료분류: """&$H19&""", 조리방식: """&$I19&""", 조리시간: """&$J19&""", 알레르기: """&$K19&""" },") -> { 카테고리: "한식", 음식: "갈비탕", 음식구분: "국/탕", 제철: "사계절", 재료: "소갈비, 당면, 대파, 무", 식사구분: ["점심", "저녁"], 영양분류: "고단백+국물", 주재료분류: "육류", 조리방식: "탕", 조리시간: "1시간", 알레르기: "없음" },
B20: 한식 | C20: 국밥 | D20: 국/탕 | E20: 사계절 | F20: 돼지고기, 부추, 밥, 파 | G20: 단백질+탄수화물 | H20: 육류 | I20: 국물 | J20: 30분 | K20: 없음 | L20: Y | M20: Y | N20: Y | P20: =IF($C20="","",_xlfn.TEXTJOIN(", ",TRUE,IF(UPPER(TRIM($L20))="Y","아침",""),IF(UPPER(TRIM($M20))="Y","점심",""),IF(UPPER(TRIM($N20))="Y","저녁",""))) -> 아침, 점심, 저녁 | Q20: =IF($C20="","","{ 카테고리: """&$B20&""", 음식: """&$C20&""", 음식구분: """&$D20&""", 제철: """&$E20&""", 재료: """&$F20&""", 식사구분: ["&_xlfn.TEXTJOIN(", ",TRUE,IF(UPPER(TRIM($L20))="Y",CHAR(34)&"아침"&CHAR(34),""),IF(UPPER(TRIM($M20))="Y",CHAR(34)&"점심"&CHAR(34),""),IF(UPPER(TRIM($N20))="Y",CHAR(34)&"저녁"&CHAR(34),""))&"], 영양분류: """&$G20&""", 주재료분류: """&$H20&""", 조리방식: """&$I20&""", 조리시간: """&$J20&""", 알레르기: """&$K20&""" },") -> { 카테고리: "한식", 음식: "국밥", 음식구분: "국/탕", 제철: "사계절", 재료: "돼지고기, 부추, 밥, 파", 식사구분: ["아침", "점심", "저녁"], 영양분류: "단백질+탄수화물", 주재료분류: "육류", 조리방식: "국물", 조리시간: "30분", 알레르기: "없음" },
B21: 한식 | C21: 고등어구이 | D21: 메인반찬 | E21: 9월~11월 | F21: 고등어, 레몬 | G21: 고단백+오메가3 | H21: 생선 | I21: 구이 | J21: 20분 | K21: 생선 | M21: Y | N21: Y | P21: =IF($C21="","",_xlfn.TEXTJOIN(", ",TRUE,IF(UPPER(TRIM($L21))="Y","아침",""),IF(UPPER(TRIM($M21))="Y","점심",""),IF(UPPER(TRIM($N21))="Y","저녁",""))) -> 점심, 저녁 | Q21: =IF($C21="","","{ 카테고리: """&$B21&""", 음식: """&$C21&""", 음식구분: """&$D21&""", 제철: """&$E21&""", 재료: """&$F21&""", 식사구분: ["&_xlfn.TEXTJOIN(", ",TRUE,IF(UPPER(TRIM($L21))="Y",CHAR(34)&"아침"&CHAR(34),""),IF(UPPER(TRIM($M21))="Y",CHAR(34)&"점심"&CHAR(34),""),IF(UPPER(TRIM($N21))="Y",CHAR(34)&"저녁"&CHAR(34),""))&"], 영양분류: """&$G21&""", 주재료분류: """&$H21&""", 조리방식: """&$I21&""", 조리시간: """&$J21&""", 알레르기: """&$K21&""" },") -> { 카테고리: "한식", 음식: "고등어구이", 음식구분: "메인반찬", 제철: "9월~11월", 재료: "고등어, 레몬", 식사구분: ["점심", "저녁"], 영양분류: "고단백+오메가3", 주재료분류: "생선", 조리방식: "구이", 조리시간: "20분", 알레르기: "생선" },
B22: 한식 | C22: 갈치구이 | D22: 메인반찬 | E22: 7월~10월 | F22: 갈치 | G22: 고단백 | H22: 생선 | I22: 구이 | J22: 20분 | K22: 생선 | M22: Y | N22: Y | P22: =IF($C22="","",_xlfn.TEXTJOIN(", ",TRUE,IF(UPPER(TRIM($L22))="Y","아침",""),IF(UPPER(TRIM($M22))="Y","점심",""),IF(UPPER(TRIM($N22))="Y","저녁",""))) -> 점심, 저녁 | Q22: =IF($C22="","","{ 카테고리: """&$B22&""", 음식: """&$C22&""", 음식구분: """&$D22&""", 제철: """&$E22&""", 재료: """&$F22&""", 식사구분: ["&_xlfn.TEXTJOIN(", ",TRUE,IF(UPPER(TRIM($L22))="Y",CHAR(34)&"아침"&CHAR(34),""),IF(UPPER(TRIM($M22))="Y",CHAR(34)&"점심"&CHAR(34),""),IF(UPPER(TRIM($N22))="Y",CHAR(34)&"저녁"&CHAR(34),""))&"], 영양분류: """&$G22&""", 주재료분류: """&$H22&""", 조리방식: """&$I22&""", 조리시간: """&$J22&""", 알레르기: """&$K22&""" },") -> { 카테고리: "한식", 음식: "갈치구이", 음식구분: "메인반찬", 제철: "7월~10월", 재료: "갈치", 식사구분: ["점심", "저녁"], 영양분류: "고단백", 주재료분류: "생선", 조리방식: "구이", 조리시간: "20분", 알레르기: "생선" },
B23: 한식 | C23: 삼치구이 | D23: 메인반찬 | E23: 10월~2월 | F23: 삼치, 레몬 | G23: 고단백+오메가3 | H23: 생선 | I23: 구이 | J23: 20분 | K23: 생선 | M23: Y | N23: Y | P23: =IF($C23="","",_xlfn.TEXTJOIN(", ",TRUE,IF(UPPER(TRIM($L23))="Y","아침",""),IF(UPPER(TRIM($M23))="Y","점심",""),IF(UPPER(TRIM($N23))="Y","저녁",""))) -> 점심, 저녁 | Q23: =IF($C23="","","{ 카테고리: """&$B23&""", 음식: """&$C23&""", 음식구분: """&$D23&""", 제철: """&$E23&""", 재료: """&$F23&""", 식사구분: ["&_xlfn.TEXTJOIN(", ",TRUE,IF(UPPER(TRIM($L23))="Y",CHAR(34)&"아침"&CHAR(34),""),IF(UPPER(TRIM($M23))="Y",CHAR(34)&"점심"&CHAR(34),""),IF(UPPER(TRIM($N23))="Y",CHAR(34)&"저녁"&CHAR(34),""))&"], 영양분류: """&$G23&""", 주재료분류: """&$H23&""", 조리방식: """&$I23&""", 조리시간: """&$J23&""", 알레르기: """&$K23&""" },") -> { 카테고리: "한식", 음식: "삼치구이", 음식구분: "메인반찬", 제철: "10월~2월", 재료: "삼치, 레몬", 식사구분: ["점심", "저녁"], 영양분류: "고단백+오메가3", 주재료분류: "생선", 조리방식: "구이", 조리시간: "20분", 알레르기: "생선" },
B24: 한식 | C24: 임연수구이 | D24: 메인반찬 | E24: 11월~3월 | F24: 임연수 | G24: 고단백 | H24: 생선 | I24: 구이 | J24: 20분 | K24: 생선 | M24: Y | N24: Y | P24: =IF($C24="","",_xlfn.TEXTJOIN(", ",TRUE,IF(UPPER(TRIM($L24))="Y","아침",""),IF(UPPER(TRIM($M24))="Y","점심",""),IF(UPPER(TRIM($N24))="Y","저녁",""))) -> 점심, 저녁 | Q24: =IF($C24="","","{ 카테고리: """&$B24&""", 음식: """&$C24&""", 음식구분: """&$D24&""", 제철: """&$E24&""", 재료: """&$F24&""", 식사구분: ["&_xlfn.TEXTJOIN(", ",TRUE,IF(UPPER(TRIM($L24))="Y",CHAR(34)&"아침"&CHAR(34),""),IF(UPPER(TRIM($M24))="Y",CHAR(34)&"점심"&CHAR(34),""),IF(UPPER(TRIM($N24))="Y",CHAR(34)&"저녁"&CHAR(34),""))&"], 영양분류: """&$G24&""", 주재료분류: """&$H24&""", 조리방식: """&$I24&""", 조리시간: """&$J24&""", 알레르기: """&$K24&""" },") -> { 카테고리: "한식", 음식: "임연수구이", 음식구분: "메인반찬", 제철: "11월~3월", 재료: "임연수", 식사구분: ["점심", "저녁"], 영양분류: "고단백", 주재료분류: "생선", 조리방식: "구이", 조리시간: "20분", 알레르기: "생선" },
B25: 한식 | C25: 꽁치구이 | D25: 메인반찬 | E25: 10월~11월 | F25: 꽁치 | G25: 고단백+오메가3 | H25: 생선 | I25: 구이 | J25: 20분 | K25: 생선 | M25: Y | N25: Y | P25: =IF($C25="","",_xlfn.TEXTJOIN(", ",TRUE,IF(UPPER(TRIM($L25))="Y","아침",""),IF(UPPER(TRIM($M25))="Y","점심",""),IF(UPPER(TRIM($N25))="Y","저녁",""))) -> 점심, 저녁 | Q25: =IF($C25="","","{ 카테고리: """&$B25&""", 음식: """&$C25&""", 음식구분: """&$D25&""", 제철: """&$E25&""", 재료: """&$F25&""", 식사구분: ["&_xlfn.TEXTJOIN(", ",TRUE,IF(UPPER(TRIM($L25))="Y",CHAR(34)&"아침"&CHAR(34),""),IF(UPPER(TRIM($M25))="Y",CHAR(34)&"점심"&CHAR(34),""),IF(UPPER(TRIM($N25))="Y",CHAR(34)&"저녁"&CHAR(34),""))&"], 영양분류: """&$G25&""", 주재료분류: """&$H25&""", 조리방식: """&$I25&""", 조리시간: """&$J25&""", 알레르기: """&$K25&""" },") -> { 카테고리: "한식", 음식: "꽁치구이", 음식구분: "메인반찬", 제철: "10월~11월", 재료: "꽁치", 식사구분: ["점심", "저녁"], 영양분류: "고단백+오메가3", 주재료분류: "생선", 조리방식: "구이", 조리시간: "20분", 알레르기: "생선" },
B26: 중식 | C26: 짜장면 | D26: 면 | E26: 사계절 | F26: 돼지고기, 양파, 양배추, 면 | G26: 탄수화물 | H26: 면 | I26: 볶음 | J26: 30분 | K26: 밀 | M26: Y | N26: Y | P26: =IF($C26="","",_xlfn.TEXTJOIN(", ",TRUE,IF(UPPER(TRIM($L26))="Y","아침",""),IF(UPPER(TRIM($M26))="Y","점심",""),IF(UPPER(TRIM($N26))="Y","저녁",""))) -> 점심, 저녁 | Q26: =IF($C26="","","{ 카테고리: """&$B26&""", 음식: """&$C26&""", 음식구분: """&$D26&""", 제철: """&$E26&""", 재료: """&$F26&""", 식사구분: ["&_xlfn.TEXTJOIN(", ",TRUE,IF(UPPER(TRIM($L26))="Y",CHAR(34)&"아침"&CHAR(34),""),IF(UPPER(TRIM($M26))="Y",CHAR(34)&"점심"&CHAR(34),""),IF(UPPER(TRIM($N26))="Y",CHAR(34)&"저녁"&CHAR(34),""))&"], 영양분류: """&$G26&""", 주재료분류: """&$H26&""", 조리방식: """&$I26&""", 조리시간: """&$J26&""", 알레르기: """&$K26&""" },") -> { 카테고리: "중식", 음식: "짜장면", 음식구분: "면", 제철: "사계절", 재료: "돼지고기, 양파, 양배추, 면", 식사구분: ["점심", "저녁"], 영양분류: "탄수화물", 주재료분류: "면", 조리방식: "볶음", 조리시간: "30분", 알레르기: "밀" },
B27: 중식 | C27: 짬뽕 | D27: 메인반찬 | E27: 사계절 | F27: 오징어, 홍합, 새우, 양파, 면 | G27: 해산물+국물 | H27: 해산물 | I27: 국물 | J27: 30분 | K27: 새우, 조개류, 밀 | M27: Y | N27: Y | P27: =IF($C27="","",_xlfn.TEXTJOIN(", ",TRUE,IF(UPPER(TRIM($L27))="Y","아침",""),IF(UPPER(TRIM($M27))="Y","점심",""),IF(UPPER(TRIM($N27))="Y","저녁",""))) -> 점심, 저녁 | Q27: =IF($C27="","","{ 카테고리: """&$B27&""", 음식: """&$C27&""", 음식구분: """&$D27&""", 제철: """&$E27&""", 재료: """&$F27&""", 식사구분: ["&_xlfn.TEXTJOIN(", ",TRUE,IF(UPPER(TRIM($L27))="Y",CHAR(34)&"아침"&CHAR(34),""),IF(UPPER(TRIM($M27))="Y",CHAR(34)&"점심"&CHAR(34),""),IF(UPPER(TRIM($N27))="Y",CHAR(34)&"저녁"&CHAR(34),""))&"], 영양분류: """&$G27&""", 주재료분류: """&$H27&""", 조리방식: """&$I27&""", 조리시간: """&$J27&""", 알레르기: """&$K27&""" },") -> { 카테고리: "중식", 음식: "짬뽕", 음식구분: "메인반찬", 제철: "사계절", 재료: "오징어, 홍합, 새우, 양파, 면", 식사구분: ["점심", "저녁"], 영양분류: "해산물+국물", 주재료분류: "해산물", 조리방식: "국물", 조리시간: "30분", 알레르기: "새우, 조개류, 밀" },
B28: 중식 | C28: 탕수육 | D28: 메인반찬 | E28: 사계절 | F28: 돼지고기, 양파, 목이버섯, 당근 | G28: 고단백+튀김 | H28: 육류 | I28: 튀김 | J28: 40분 | K28: 밀 | M28: Y | N28: Y | P28: =IF($C28="","",_xlfn.TEXTJOIN(", ",TRUE,IF(UPPER(TRIM($L28))="Y","아침",""),IF(UPPER(TRIM($M28))="Y","점심",""),IF(UPPER(TRIM($N28))="Y","저녁",""))) -> 점심, 저녁 | Q28: =IF($C28="","","{ 카테고리: """&$B28&""", 음식: """&$C28&""", 음식구분: """&$D28&""", 제철: """&$E28&""", 재료: """&$F28&""", 식사구분: ["&_xlfn.TEXTJOIN(", ",TRUE,IF(UPPER(TRIM($L28))="Y",CHAR(34)&"아침"&CHAR(34),""),IF(UPPER(TRIM($M28))="Y",CHAR(34)&"점심"&CHAR(34),""),IF(UPPER(TRIM($N28))="Y",CHAR(34)&"저녁"&CHAR(34),""))&"], 영양분류: """&$G28&""", 주재료분류: """&$H28&""", 조리방식: """&$I28&""", 조리시간: """&$J28&""", 알레르기: """&$K28&""" },") -> { 카테고리: "중식", 음식: "탕수육", 음식구분: "메인반찬", 제철: "사계절", 재료: "돼지고기, 양파, 목이버섯, 당근", 식사구분: ["점심", "저녁"], 영양분류: "고단백+튀김", 주재료분류: "육류", 조리방식: "튀김", 조리시간: "40분", 알레르기: "밀" },
B29: 중식 | C29: 마파두부 | D29: 메인반찬 | E29: 사계절 | F29: 두부, 돼지고기 다짐육, 파 | G29: 단백질 | H29: 두부 | I29: 볶음 | J29: 25분 | K29: 대두 | M29: Y | N29: Y | P29: =IF($C29="","",_xlfn.TEXTJOIN(", ",TRUE,IF(UPPER(TRIM($L29))="Y","아침",""),IF(UPPER(TRIM($M29))="Y","점심",""),IF(UPPER(TRIM($N29))="Y","저녁",""))) -> 점심, 저녁 | Q29: =IF($C29="","","{ 카테고리: """&$B29&""", 음식: """&$C29&""", 음식구분: """&$D29&""", 제철: """&$E29&""", 재료: """&$F29&""", 식사구분: ["&_xlfn.TEXTJOIN(", ",TRUE,IF(UPPER(TRIM($L29))="Y",CHAR(34)&"아침"&CHAR(34),""),IF(UPPER(TRIM($M29))="Y",CHAR(34)&"점심"&CHAR(34),""),IF(UPPER(TRIM($N29))="Y",CHAR(34)&"저녁"&CHAR(34),""))&"], 영양분류: """&$G29&""", 주재료분류: """&$H29&""", 조리방식: """&$I29&""", 조리시간: """&$J29&""", 알레르기: """&$K29&""" },") -> { 카테고리: "중식", 음식: "마파두부", 음식구분: "메인반찬", 제철: "사계절", 재료: "두부, 돼지고기 다짐육, 파", 식사구분: ["점심", "저녁"], 영양분류: "단백질", 주재료분류: "두부", 조리방식: "볶음", 조리시간: "25분", 알레르기: "대두" },
B30: 중식 | C30: 깐풍기 | D30: 메인반찬 | E30: 사계절 | F30: 닭고기, 양상추, 피망 | G30: 고단백+튀김 | H30: 육류 | I30: 튀김 | J30: 40분 | K30: 밀 | M30: Y | N30: Y | P30: =IF($C30="","",_xlfn.TEXTJOIN(", ",TRUE,IF(UPPER(TRIM($L30))="Y","아침",""),IF(UPPER(TRIM($M30))="Y","점심",""),IF(UPPER(TRIM($N30))="Y","저녁",""))) -> 점심, 저녁 | Q30: =IF($C30="","","{ 카테고리: """&$B30&""", 음식: """&$C30&""", 음식구분: """&$D30&""", 제철: """&$E30&""", 재료: """&$F30&""", 식사구분: ["&_xlfn.TEXTJOIN(", ",TRUE,IF(UPPER(TRIM($L30))="Y",CHAR(34)&"아침"&CHAR(34),""),IF(UPPER(TRIM($M30))="Y",CHAR(34)&"점심"&CHAR(34),""),IF(UPPER(TRIM($N30))="Y",CHAR(34)&"저녁"&CHAR(34),""))&"], 영양분류: """&$G30&""", 주재료분류: """&$H30&""", 조리방식: """&$I30&""", 조리시간: """&$J30&""", 알레르기: """&$K30&""" },") -> { 카테고리: "중식", 음식: "깐풍기", 음식구분: "메인반찬", 제철: "사계절", 재료: "닭고기, 양상추, 피망", 식사구분: ["점심", "저녁"], 영양분류: "고단백+튀김", 주재료분류: "육류", 조리방식: "튀김", 조리시간: "40분", 알레르기: "밀" },
B31: 중식 | C31: 볶음밥 | D31: 메인반찬 | E31: 사계절 | F31: 밥, 계란, 파, 새우 | G31: 탄수화물+단백질 | H31: 밥 | I31: 볶음 | J31: 20분 | K31: 계란, 새우 | L31: Y | M31: Y | N31: Y | P31: =IF($C31="","",_xlfn.TEXTJOIN(", ",TRUE,IF(UPPER(TRIM($L31))="Y","아침",""),IF(UPPER(TRIM($M31))="Y","점심",""),IF(UPPER(TRIM($N31))="Y","저녁",""))) -> 아침, 점심, 저녁 | Q31: =IF($C31="","","{ 카테고리: """&$B31&""", 음식: """&$C31&""", 음식구분: """&$D31&""", 제철: """&$E31&""", 재료: """&$F31&""", 식사구분: ["&_xlfn.TEXTJOIN(", ",TRUE,IF(UPPER(TRIM($L31))="Y",CHAR(34)&"아침"&CHAR(34),""),IF(UPPER(TRIM($M31))="Y",CHAR(34)&"점심"&CHAR(34),""),IF(UPPER(TRIM($N31))="Y",CHAR(34)&"저녁"&CHAR(34),""))&"], 영양분류: """&$G31&""", 주재료분류: """&$H31&""", 조리방식: """&$I31&""", 조리시간: """&$J31&""", 알레르기: """&$K31&""" },") -> { 카테고리: "중식", 음식: "볶음밥", 음식구분: "메인반찬", 제철: "사계절", 재료: "밥, 계란, 파, 새우", 식사구분: ["아침", "점심", "저녁"], 영양분류: "탄수화물+단백질", 주재료분류: "밥", 조리방식: "볶음", 조리시간: "20분", 알레르기: "계란, 새우" },
B32: 일식 | C32: 초밥 | D32: 메인반찬 | E32: 사계절 | F32: 생선, 밥 | G32: 고단백 | H32: 생선 | I32: 생식 | J32: 30분 | K32: 생선 | M32: Y | N32: Y | P32: =IF($C32="","",_xlfn.TEXTJOIN(", ",TRUE,IF(UPPER(TRIM($L32))="Y","아침",""),IF(UPPER(TRIM($M32))="Y","점심",""),IF(UPPER(TRIM($N32))="Y","저녁",""))) -> 점심, 저녁 | Q32: =IF($C32="","","{ 카테고리: """&$B32&""", 음식: """&$C32&""", 음식구분: """&$D32&""", 제철: """&$E32&""", 재료: """&$F32&""", 식사구분: ["&_xlfn.TEXTJOIN(", ",TRUE,IF(UPPER(TRIM($L32))="Y",CHAR(34)&"아침"&CHAR(34),""),IF(UPPER(TRIM($M32))="Y",CHAR(34)&"점심"&CHAR(34),""),IF(UPPER(TRIM($N32))="Y",CHAR(34)&"저녁"&CHAR(34),""))&"], 영양분류: """&$G32&""", 주재료분류: """&$H32&""", 조리방식: """&$I32&""", 조리시간: """&$J32&""", 알레르기: """&$K32&""" },") -> { 카테고리: "일식", 음식: "초밥", 음식구분: "메인반찬", 제철: "사계절", 재료: "생선, 밥", 식사구분: ["점심", "저녁"], 영양분류: "고단백", 주재료분류: "생선", 조리방식: "생식", 조리시간: "30분", 알레르기: "생선" },
B33: 일식 | C33: 돈카츠 | D33: 메인반찬 | E33: 사계절 | F33: 돼지고기 등심, 양배추 | G33: 고단백+튀김 | H33: 육류 | I33: 튀김 | J33: 35분 | K33: 밀, 계란 | M33: Y | N33: Y | P33: =IF($C33="","",_xlfn.TEXTJOIN(", ",TRUE,IF(UPPER(TRIM($L33))="Y","아침",""),IF(UPPER(TRIM($M33))="Y","점심",""),IF(UPPER(TRIM($N33))="Y","저녁",""))) -> 점심, 저녁 | Q33: =IF($C33="","","{ 카테고리: """&$B33&""", 음식: """&$C33&""", 음식구분: """&$D33&""", 제철: """&$E33&""", 재료: """&$F33&""", 식사구분: ["&_xlfn.TEXTJOIN(", ",TRUE,IF(UPPER(TRIM($L33))="Y",CHAR(34)&"아침"&CHAR(34),""),IF(UPPER(TRIM($M33))="Y",CHAR(34)&"점심"&CHAR(34),""),IF(UPPER(TRIM($N33))="Y",CHAR(34)&"저녁"&CHAR(34),""))&"], 영양분류: """&$G33&""", 주재료분류: """&$H33&""", 조리방식: """&$I33&""", 조리시간: """&$J33&""", 알레르기: """&$K33&""" },") -> { 카테고리: "일식", 음식: "돈카츠", 음식구분: "메인반찬", 제철: "사계절", 재료: "돼지고기 등심, 양배추", 식사구분: ["점심", "저녁"], 영양분류: "고단백+튀김", 주재료분류: "육류", 조리방식: "튀김", 조리시간: "35분", 알레르기: "밀, 계란" },
B34: 일식 | C34: 라멘 | D34: 면 | E34: 사계절 | F34: 라멘 면, 돼지고기 챠슈, 숙주, 반숙란 | G34: 탄수화물+국물 | H34: 면 | I34: 국물 | J34: 30분 | K34: 밀, 계란 | M34: Y | N34: Y | P34: =IF($C34="","",_xlfn.TEXTJOIN(", ",TRUE,IF(UPPER(TRIM($L34))="Y","아침",""),IF(UPPER(TRIM($M34))="Y","점심",""),IF(UPPER(TRIM($N34))="Y","저녁",""))) -> 점심, 저녁 | Q34: =IF($C34="","","{ 카테고리: """&$B34&""", 음식: """&$C34&""", 음식구분: """&$D34&""", 제철: """&$E34&""", 재료: """&$F34&""", 식사구분: ["&_xlfn.TEXTJOIN(", ",TRUE,IF(UPPER(TRIM($L34))="Y",CHAR(34)&"아침"&CHAR(34),""),IF(UPPER(TRIM($M34))="Y",CHAR(34)&"점심"&CHAR(34),""),IF(UPPER(TRIM($N34))="Y",CHAR(34)&"저녁"&CHAR(34),""))&"], 영양분류: """&$G34&""", 주재료분류: """&$H34&""", 조리방식: """&$I34&""", 조리시간: """&$J34&""", 알레르기: """&$K34&""" },") -> { 카테고리: "일식", 음식: "라멘", 음식구분: "면", 제철: "사계절", 재료: "라멘 면, 돼지고기 챠슈, 숙주, 반숙란", 식사구분: ["점심", "저녁"], 영양분류: "탄수화물+국물", 주재료분류: "면", 조리방식: "국물", 조리시간: "30분", 알레르기: "밀, 계란" },
B35: 일식 | C35: 우동 | D35: 면 | E35: 겨울 | F35: 우동 면, 어묵, 대파, 쑥갓 | G35: 가벼운 국물 | H35: 면 | I35: 국물 | J35: 20분 | K35: 밀, 생선 | L35: Y | M35: Y | N35: Y | P35: =IF($C35="","",_xlfn.TEXTJOIN(", ",TRUE,IF(UPPER(TRIM($L35))="Y","아침",""),IF(UPPER(TRIM($M35))="Y","점심",""),IF(UPPER(TRIM($N35))="Y","저녁",""))) -> 아침, 점심, 저녁 | Q35: =IF($C35="","","{ 카테고리: """&$B35&""", 음식: """&$C35&""", 음식구분: """&$D35&""", 제철: """&$E35&""", 재료: """&$F35&""", 식사구분: ["&_xlfn.TEXTJOIN(", ",TRUE,IF(UPPER(TRIM($L35))="Y",CHAR(34)&"아침"&CHAR(34),""),IF(UPPER(TRIM($M35))="Y",CHAR(34)&"점심"&CHAR(34),""),IF(UPPER(TRIM($N35))="Y",CHAR(34)&"저녁"&CHAR(34),""))&"], 영양분류: """&$G35&""", 주재료분류: """&$H35&""", 조리방식: """&$I35&""", 조리시간: """&$J35&""", 알레르기: """&$K35&""" },") -> { 카테고리: "일식", 음식: "우동", 음식구분: "면", 제철: "겨울", 재료: "우동 면, 어묵, 대파, 쑥갓", 식사구분: ["아침", "점심", "저녁"], 영양분류: "가벼운 국물", 주재료분류: "면", 조리방식: "국물", 조리시간: "20분", 알레르기: "밀, 생선" },
B36: 일식 | C36: 사케동 (연어덮밥) | D36: 메인반찬 | E36: 사계절 | F36: 연어, 밥, 양파 | G36: 고단백+오메가3 | H36: 생선 | I36: 덮밥 | J36: 20분 | K36: 생선 | M36: Y | N36: Y | P36: =IF($C36="","",_xlfn.TEXTJOIN(", ",TRUE,IF(UPPER(TRIM($L36))="Y","아침",""),IF(UPPER(TRIM($M36))="Y","점심",""),IF(UPPER(TRIM($N36))="Y","저녁",""))) -> 점심, 저녁 | Q36: =IF($C36="","","{ 카테고리: """&$B36&""", 음식: """&$C36&""", 음식구분: """&$D36&""", 제철: """&$E36&""", 재료: """&$F36&""", 식사구분: ["&_xlfn.TEXTJOIN(", ",TRUE,IF(UPPER(TRIM($L36))="Y",CHAR(34)&"아침"&CHAR(34),""),IF(UPPER(TRIM($M36))="Y",CHAR(34)&"점심"&CHAR(34),""),IF(UPPER(TRIM($N36))="Y",CHAR(34)&"저녁"&CHAR(34),""))&"], 영양분류: """&$G36&""", 주재료분류: """&$H36&""", 조리방식: """&$I36&""", 조리시간: """&$J36&""", 알레르기: """&$K36&""" },") -> { 카테고리: "일식", 음식: "사케동 (연어덮밥)", 음식구분: "메인반찬", 제철: "사계절", 재료: "연어, 밥, 양파", 식사구분: ["점심", "저녁"], 영양분류: "고단백+오메가3", 주재료분류: "생선", 조리방식: "덮밥", 조리시간: "20분", 알레르기: "생선" },
B37: 일식 | C37: 텐동 (튀김덮밥) | D37: 메인반찬 | E37: 사계절 | F37: 새우, 단호박, 가지, 밥 | G37: 탄수화물+튀김 | H37: 해산물 | I37: 튀김 | J37: 35분 | K37: 새우, 밀 | M37: Y | N37: Y | P37: =IF($C37="","",_xlfn.TEXTJOIN(", ",TRUE,IF(UPPER(TRIM($L37))="Y","아침",""),IF(UPPER(TRIM($M37))="Y","점심",""),IF(UPPER(TRIM($N37))="Y","저녁",""))) -> 점심, 저녁 | Q37: =IF($C37="","","{ 카테고리: """&$B37&""", 음식: """&$C37&""", 음식구분: """&$D37&""", 제철: """&$E37&""", 재료: """&$F37&""", 식사구분: ["&_xlfn.TEXTJOIN(", ",TRUE,IF(UPPER(TRIM($L37))="Y",CHAR(34)&"아침"&CHAR(34),""),IF(UPPER(TRIM($M37))="Y",CHAR(34)&"점심"&CHAR(34),""),IF(UPPER(TRIM($N37))="Y",CHAR(34)&"저녁"&CHAR(34),""))&"], 영양분류: """&$G37&""", 주재료분류: """&$H37&""", 조리방식: """&$I37&""", 조리시간: """&$J37&""", 알레르기: """&$K37&""" },") -> { 카테고리: "일식", 음식: "텐동 (튀김덮밥)", 음식구분: "메인반찬", 제철: "사계절", 재료: "새우, 단호박, 가지, 밥", 식사구분: ["점심", "저녁"], 영양분류: "탄수화물+튀김", 주재료분류: "해산물", 조리방식: "튀김", 조리시간: "35분", 알레르기: "새우, 밀" },
B38: 양식 | C38: 파스타 | D38: 메인반찬 | E38: 사계절 | F38: 파스타 면, 토마토, 마늘, 베이컨 | G38: 탄수화물 | H38: 면 | I38: 볶음 | J38: 25분 | K38: 밀 | M38: Y | N38: Y | P38: =IF($C38="","",_xlfn.TEXTJOIN(", ",TRUE,IF(UPPER(TRIM($L38))="Y","아침",""),IF(UPPER(TRIM($M38))="Y","점심",""),IF(UPPER(TRIM($N38))="Y","저녁",""))) -> 점심, 저녁 | Q38: =IF($C38="","","{ 카테고리: """&$B38&""", 음식: """&$C38&""", 음식구분: """&$D38&""", 제철: """&$E38&""", 재료: """&$F38&""", 식사구분: ["&_xlfn.TEXTJOIN(", ",TRUE,IF(UPPER(TRIM($L38))="Y",CHAR(34)&"아침"&CHAR(34),""),IF(UPPER(TRIM($M38))="Y",CHAR(34)&"점심"&CHAR(34),""),IF(UPPER(TRIM($N38))="Y",CHAR(34)&"저녁"&CHAR(34),""))&"], 영양분류: """&$G38&""", 주재료분류: """&$H38&""", 조리방식: """&$I38&""", 조리시간: """&$J38&""", 알레르기: """&$K38&""" },") -> { 카테고리: "양식", 음식: "파스타", 음식구분: "메인반찬", 제철: "사계절", 재료: "파스타 면, 토마토, 마늘, 베이컨", 식사구분: ["점심", "저녁"], 영양분류: "탄수화물", 주재료분류: "면", 조리방식: "볶음", 조리시간: "25분", 알레르기: "밀" },
B39: 양식 | C39: 스테이크 | D39: 메인반찬 | E39: 사계절 | F39: 소고기 안심, 아스파라거스, 방울토마토 | G39: 고단백 | H39: 육류 | I39: 구이 | J39: 30분 | K39: 없음 | N39: Y | P39: =IF($C39="","",_xlfn.TEXTJOIN(", ",TRUE,IF(UPPER(TRIM($L39))="Y","아침",""),IF(UPPER(TRIM($M39))="Y","점심",""),IF(UPPER(TRIM($N39))="Y","저녁",""))) -> 저녁 | Q39: =IF($C39="","","{ 카테고리: """&$B39&""", 음식: """&$C39&""", 음식구분: """&$D39&""", 제철: """&$E39&""", 재료: """&$F39&""", 식사구분: ["&_xlfn.TEXTJOIN(", ",TRUE,IF(UPPER(TRIM($L39))="Y",CHAR(34)&"아침"&CHAR(34),""),IF(UPPER(TRIM($M39))="Y",CHAR(34)&"점심"&CHAR(34),""),IF(UPPER(TRIM($N39))="Y",CHAR(34)&"저녁"&CHAR(34),""))&"], 영양분류: """&$G39&""", 주재료분류: """&$H39&""", 조리방식: """&$I39&""", 조리시간: """&$J39&""", 알레르기: """&$K39&""" },") -> { 카테고리: "양식", 음식: "스테이크", 음식구분: "메인반찬", 제철: "사계절", 재료: "소고기 안심, 아스파라거스, 방울토마토", 식사구분: ["저녁"], 영양분류: "고단백", 주재료분류: "육류", 조리방식: "구이", 조리시간: "30분", 알레르기: "없음" },
B40: 양식 | C40: 피자 | D40: 메인반찬 | E40: 사계절 | F40: 밀가루 도우, 치즈, 페퍼로니, 양송이 | G40: 고열량 | H40: 밀 | I40: 구이 | J40: 40분 | K40: 밀, 우유 | M40: Y | N40: Y | P40: =IF($C40="","",_xlfn.TEXTJOIN(", ",TRUE,IF(UPPER(TRIM($L40))="Y","아침",""),IF(UPPER(TRIM($M40))="Y","점심",""),IF(UPPER(TRIM($N40))="Y","저녁",""))) -> 점심, 저녁 | Q40: =IF($C40="","","{ 카테고리: """&$B40&""", 음식: """&$C40&""", 음식구분: """&$D40&""", 제철: """&$E40&""", 재료: """&$F40&""", 식사구분: ["&_xlfn.TEXTJOIN(", ",TRUE,IF(UPPER(TRIM($L40))="Y",CHAR(34)&"아침"&CHAR(34),""),IF(UPPER(TRIM($M40))="Y",CHAR(34)&"점심"&CHAR(34),""),IF(UPPER(TRIM($N40))="Y",CHAR(34)&"저녁"&CHAR(34),""))&"], 영양분류: """&$G40&""", 주재료분류: """&$H40&""", 조리방식: """&$I40&""", 조리시간: """&$J40&""", 알레르기: """&$K40&""" },") -> { 카테고리: "양식", 음식: "피자", 음식구분: "메인반찬", 제철: "사계절", 재료: "밀가루 도우, 치즈, 페퍼로니, 양송이", 식사구분: ["점심", "저녁"], 영양분류: "고열량", 주재료분류: "밀", 조리방식: "구이", 조리시간: "40분", 알레르기: "밀, 우유" },
...

Sheet 요약
A1: 식단 데이터 관리 요약
A3: 총 음식 수 | B3: =COUNTA(음식DB!$C$2:$C$500) -> 87 | D3: 카테고리별 개수 | E3: 개수 | G3: 음식구분별 개수 | H3: 개수
A4: 한식 항목 수 | B4: =COUNTIF(음식DB!$B$2:$B$500,"한식") -> 51 | D4: 간단식 | E4: =COUNTIF(음식DB!$B$2:$B$500,D4) -> 8 | G4: 간단식 | H4: =COUNTIF(음식DB!$D$2:$D$500,G4) -> 8
A5: 아침 가능 | B5: =COUNTIF(음식DB!$L$2:$L$500,"Y") -> 32 | D5: 분식 | E5: =COUNTIF(음식DB!$B$2:$B$500,D5) -> 5 | G5: 국/탕 | H5: =COUNTIF(음식DB!$D$2:$D$500,G5) -> 10
A6: 점심 가능 | B6: =COUNTIF(음식DB!$M$2:$M$500,"Y") -> 79 | D6: 아시안 | E6: =COUNTIF(음식DB!$B$2:$B$500,D6) -> 5 | G6: 김치/젓갈/장 | H6: =COUNTIF(음식DB!$D$2:$D$500,G6) -> 5
A7: 저녁 가능 | B7: =COUNTIF(음식DB!$N$2:$N$500,"Y") -> 79 | D7: 양식 | E7: =COUNTIF(음식DB!$B$2:$B$500,D7) -> 6 | G7: 메인반찬 | H7: =COUNTIF(음식DB!$D$2:$D$500,G7) -> 38
D8: 일식 | E8: =COUNTIF(음식DB!$B$2:$B$500,D8) -> 6 | G8: 면 | H8: =COUNTIF(음식DB!$D$2:$D$500,G8) -> 9
D9: 중식 | E9: =COUNTIF(음식DB!$B$2:$B$500,D9) -> 6 | G9: 밑반찬 | H9: =COUNTIF(음식DB!$D$2:$D$500,G9) -> 11
D10: 한식 | E10: =COUNTIF(음식DB!$B$2:$B$500,D10) -> 51 | G10: 찌개 | H10: =COUNTIF(음식DB!$D$2:$D$500,G10) -> 6
A13: 제철 구분 | B13: 개수
A14: 10월~11월 | B14: =COUNTIF(음식DB!$E$2:$E$500,A14) -> 1
A15: 10월~2월 | B15: =COUNTIF(음식DB!$E$2:$E$500,A15) -> 1
A16: 11월~3월 | B16: =COUNTIF(음식DB!$E$2:$E$500,A16) -> 1
A17: 7월~10월 | B17: =COUNTIF(음식DB!$E$2:$E$500,A17) -> 2
A18: 7월~11월 | B18: =COUNTIF(음식DB!$E$2:$E$500,A18) -> 1
A19: 9월~11월 | B19: =COUNTIF(음식DB!$E$2:$E$500,A19) -> 1
A20: 가을 | B20: =COUNTIF(음식DB!$E$2:$E$500,A20) -> 2
A21: 겨울 | B21: =COUNTIF(음식DB!$E$2:$E$500,A21) -> 7
A22: 봄 | B22: =COUNTIF(음식DB!$E$2:$E$500,A22) -> 4
A23: 사계절 | B23: =COUNTIF(음식DB!$E$2:$E$500,A23) -> 55
A24: 여름 | B24: =COUNTIF(음식DB!$E$2:$E$500,A24) -> 12
A27: data.js 복사 사용 방법
A28: 1 | B28: 음식DB 시트에서 카테고리~알레르기 정보를 입력합니다.
A29: 2 | B29: 아침가능/점심가능/저녁가능 열에는 해당 식사에 사용 가능할 때만 Y를 입력하고, 아니면 빈칸으로 둡니다.
A30: 3 | B30: P열 식사구분 자동에는 Y 입력값에 따라 아침, 점심, 저녁이 자동 표시됩니다.
A31: 4 | B31: Q열 data.js 복사용 값을 복사하여 data.js의 foodData 배열 안에 붙여넣으면 됩니다.
A32: 예시 | B32: 아침가능=Y, 점심가능=Y, 저녁가능 빈칸 → 식사구분: ["아침", "점심"]
